2019-09-18 11:30:24.5897||ERROR|Template.Api.ActionFilters.GlobalExceptionAttribute|'System.Array' does not contain a definition for 'HasErrors':  Controller: Test  Action: GetAllTestResults System.Exception: 'System.Array' does not contain a definition for 'HasErrors':  Controller: Test  Action: GetAllTestResults ---> Microsoft.CSharp.RuntimeBinder.RuntimeBinderException: 'System.Array' does not contain a definition for 'HasErrors'
   at CallSite.Target(Closure , CallSite , Object )
   at System.Dynamic.UpdateDelegates.UpdateAndExecute1[T0,TRet](CallSite site, T0 arg0)
   at Template.Controllers.BaseController.JsonResponse(Object obj) in D:\Projects\NetCoreTemplate\Template\Template\Controllers\BaseController.cs:line 23
   at Template.Controllers.TestController.GetAllTestResults() in D:\Projects\NetCoreTemplate\Template\Template\Controllers\TestController.cs:line 42
   at Microsoft.AspNetCore.Mvc.Internal.ActionMethodExecutor.TaskOfIActionResultExecutor.Execute(IActionResultTypeMapper mapper, ObjectMethodExecutor executor, Object controller, Object[] arguments)
   at System.Threading.Tasks.ValueTask`1.get_Result()
   at Microsoft.AspNetCore.Mvc.Internal.ControllerActionInvoker.InvokeActionMethodAsync()
   at Microsoft.AspNetCore.Mvc.Internal.ControllerActionInvoker.InvokeNextActionFilterAsync()
   at Microsoft.AspNetCore.Mvc.Internal.ControllerActionInvoker.Rethrow(ActionExecutedContext context)
   at Microsoft.AspNetCore.Mvc.Internal.ControllerActionInvoker.Next(State& next, Scope& scope, Object& state, Boolean& isCompleted)
   at Microsoft.AspNetCore.Mvc.Internal.ControllerActionInvoker.InvokeInnerFilterAsync()
   at Microsoft.AspNetCore.Mvc.Internal.ResourceInvoker.InvokeNextExceptionFilterAsync()
   --- End of inner exception stack trace ---|url: https://localhost/api/Tests/Results|action: GetAllTestResults
2019-09-18 11:31:42.6015||ERROR|Template.Api.ActionFilters.GlobalExceptionAttribute|'System.Array' does not contain a definition for 'HasErrors':  Controller: Test  Action: GetAllTestResults System.Exception: 'System.Array' does not contain a definition for 'HasErrors':  Controller: Test  Action: GetAllTestResults ---> Microsoft.CSharp.RuntimeBinder.RuntimeBinderException: 'System.Array' does not contain a definition for 'HasErrors'
   at CallSite.Target(Closure , CallSite , Object )
   at Template.Controllers.BaseController.JsonResponse(Object obj) in D:\Projects\NetCoreTemplate\Template\Template\Controllers\BaseController.cs:line 23
   at Template.Controllers.TestController.GetAllTestResults() in D:\Projects\NetCoreTemplate\Template\Template\Controllers\TestController.cs:line 42
   at Microsoft.AspNetCore.Mvc.Internal.ActionMethodExecutor.TaskOfIActionResultExecutor.Execute(IActionResultTypeMapper mapper, ObjectMethodExecutor executor, Object controller, Object[] arguments)
   at System.Threading.Tasks.ValueTask`1.get_Result()
   at Microsoft.AspNetCore.Mvc.Internal.ControllerActionInvoker.InvokeActionMethodAsync()
   at Microsoft.AspNetCore.Mvc.Internal.ControllerActionInvoker.InvokeNextActionFilterAsync()
   at Microsoft.AspNetCore.Mvc.Internal.ControllerActionInvoker.Rethrow(ActionExecutedContext context)
   at Microsoft.AspNetCore.Mvc.Internal.ControllerActionInvoker.Next(State& next, Scope& scope, Object& state, Boolean& isCompleted)
   at Microsoft.AspNetCore.Mvc.Internal.ControllerActionInvoker.InvokeInnerFilterAsync()
   at Microsoft.AspNetCore.Mvc.Internal.ResourceInvoker.InvokeNextExceptionFilterAsync()
   --- End of inner exception stack trace ---|url: https://localhost/api/Tests/Results|action: GetAllTestResults
2019-09-18 11:37:49.7542||ERROR|Template.Api.ActionFilters.GlobalExceptionAttribute|'System.Array' does not contain a definition for 'HasErrors':  Controller: Test  Action: GetAllTestResults System.Exception: 'System.Array' does not contain a definition for 'HasErrors':  Controller: Test  Action: GetAllTestResults ---> Microsoft.CSharp.RuntimeBinder.RuntimeBinderException: 'System.Array' does not contain a definition for 'HasErrors'
   at CallSite.Target(Closure , CallSite , Object )
   at Template.Controllers.BaseController.JsonResponse(Object obj) in D:\Projects\NetCoreTemplate\Template\Template\Controllers\BaseController.cs:line 23
   at Template.Controllers.TestController.GetAllTestResults() in D:\Projects\NetCoreTemplate\Template\Template\Controllers\TestController.cs:line 42
   at Microsoft.AspNetCore.Mvc.Internal.ActionMethodExecutor.TaskOfIActionResultExecutor.Execute(IActionResultTypeMapper mapper, ObjectMethodExecutor executor, Object controller, Object[] arguments)
   at System.Threading.Tasks.ValueTask`1.get_Result()
   at Microsoft.AspNetCore.Mvc.Internal.ControllerActionInvoker.InvokeActionMethodAsync()
   at Microsoft.AspNetCore.Mvc.Internal.ControllerActionInvoker.InvokeNextActionFilterAsync()
   at Microsoft.AspNetCore.Mvc.Internal.ControllerActionInvoker.Rethrow(ActionExecutedContext context)
   at Microsoft.AspNetCore.Mvc.Internal.ControllerActionInvoker.Next(State& next, Scope& scope, Object& state, Boolean& isCompleted)
   at Microsoft.AspNetCore.Mvc.Internal.ControllerActionInvoker.InvokeInnerFilterAsync()
   at Microsoft.AspNetCore.Mvc.Internal.ResourceInvoker.InvokeNextExceptionFilterAsync()
   --- End of inner exception stack trace ---|url: https://localhost/api/Tests/Results|action: GetAllTestResults
2019-09-18 11:44:14.0096||ERROR|Template.Api.ActionFilters.GlobalExceptionAttribute|'System.Array' does not contain a definition for 'HasErrors':  Controller: Test  Action: GetAllTestResults System.Exception: 'System.Array' does not contain a definition for 'HasErrors':  Controller: Test  Action: GetAllTestResults ---> Microsoft.CSharp.RuntimeBinder.RuntimeBinderException: 'System.Array' does not contain a definition for 'HasErrors'
   at CallSite.Target(Closure , CallSite , Object )
   at System.Dynamic.UpdateDelegates.UpdateAndExecute1[T0,TRet](CallSite site, T0 arg0)
   at Template.Controllers.BaseController.JsonResponse(Object obj) in D:\Projects\NetCoreTemplate\Template\Template\Controllers\BaseController.cs:line 23
   at Template.Controllers.TestController.GetAllTestResults() in D:\Projects\NetCoreTemplate\Template\Template\Controllers\TestController.cs:line 42
   at Microsoft.AspNetCore.Mvc.Internal.ActionMethodExecutor.TaskOfIActionResultExecutor.Execute(IActionResultTypeMapper mapper, ObjectMethodExecutor executor, Object controller, Object[] arguments)
   at System.Threading.Tasks.ValueTask`1.get_Result()
   at Microsoft.AspNetCore.Mvc.Internal.ControllerActionInvoker.InvokeActionMethodAsync()
   at Microsoft.AspNetCore.Mvc.Internal.ControllerActionInvoker.InvokeNextActionFilterAsync()
   at Microsoft.AspNetCore.Mvc.Internal.ControllerActionInvoker.Rethrow(ActionExecutedContext context)
   at Microsoft.AspNetCore.Mvc.Internal.ControllerActionInvoker.Next(State& next, Scope& scope, Object& state, Boolean& isCompleted)
   at Microsoft.AspNetCore.Mvc.Internal.ControllerActionInvoker.InvokeInnerFilterAsync()
   at Microsoft.AspNetCore.Mvc.Internal.ResourceInvoker.InvokeNextExceptionFilterAsync()
   --- End of inner exception stack trace ---|url: https://localhost/api/Tests/Results|action: GetAllTestResults
2019-09-18 11:46:45.2678||ERROR|Template.Api.ActionFilters.GlobalExceptionAttribute|'System.Array' does not contain a definition for 'HasErrors':  Controller: Test  Action: GetAllTestResults System.Exception: 'System.Array' does not contain a definition for 'HasErrors':  Controller: Test  Action: GetAllTestResults ---> Microsoft.CSharp.RuntimeBinder.RuntimeBinderException: 'System.Array' does not contain a definition for 'HasErrors'
   at CallSite.Target(Closure , CallSite , Object )
   at Template.Controllers.BaseController.JsonResponse(Object obj) in D:\Projects\NetCoreTemplate\Template\Template\Controllers\BaseController.cs:line 23
   at Template.Controllers.TestController.GetAllTestResults() in D:\Projects\NetCoreTemplate\Template\Template\Controllers\TestController.cs:line 42
   at Microsoft.AspNetCore.Mvc.Internal.ActionMethodExecutor.TaskOfIActionResultExecutor.Execute(IActionResultTypeMapper mapper, ObjectMethodExecutor executor, Object controller, Object[] arguments)
   at System.Threading.Tasks.ValueTask`1.get_Result()
   at Microsoft.AspNetCore.Mvc.Internal.ControllerActionInvoker.InvokeActionMethodAsync()
   at Microsoft.AspNetCore.Mvc.Internal.ControllerActionInvoker.InvokeNextActionFilterAsync()
   at Microsoft.AspNetCore.Mvc.Internal.ControllerActionInvoker.Rethrow(ActionExecutedContext context)
   at Microsoft.AspNetCore.Mvc.Internal.ControllerActionInvoker.Next(State& next, Scope& scope, Object& state, Boolean& isCompleted)
   at Microsoft.AspNetCore.Mvc.Internal.ControllerActionInvoker.InvokeInnerFilterAsync()
   at Microsoft.AspNetCore.Mvc.Internal.ResourceInvoker.InvokeNextExceptionFilterAsync()
   --- End of inner exception stack trace ---|url: https://localhost/api/Tests/Results|action: GetAllTestResults
2019-09-18 17:42:59.7987||ERROR|Template.Api.ActionFilters.GlobalExceptionAttribute|
Unmapped members were found. Review the types and members below.
Add a custom mapping expression, ignore, add a custom resolver, or modify the source/destination type
For no matching constructor, add a no-arg ctor, add optional arguments, or map all of the constructor parameters
===================================================================
AutoMapper created this type map for you, but your types cannot be mapped using the current configuration.
LoginDTO -> ApplicationUser (Destination member list)
Template.Core.DTO.LoginDTO -> Template.Core.Entity.ApplicationUser (Destination member list)

Unmapped properties:
CreatedBy
CreatedOn
LastModifiedBy
LastModifiedOn
IsDeleted
UserType
FirstName
LastName
DateOfBirth
IsActive
Id
NormalizedUserName
Email
NormalizedEmail
EmailConfirmed
PasswordHash
SecurityStamp
ConcurrencyStamp
PhoneNumber
PhoneNumberConfirmed
TwoFactorEnabled
LockoutEnd
LockoutEnabled
AccessFailedCount
:  Controller: Auth  Action: Post System.Exception: 
Unmapped members were found. Review the types and members below.
Add a custom mapping expression, ignore, add a custom resolver, or modify the source/destination type
For no matching constructor, add a no-arg ctor, add optional arguments, or map all of the constructor parameters
===================================================================
AutoMapper created this type map for you, but your types cannot be mapped using the current configuration.
LoginDTO -> ApplicationUser (Destination member list)
Template.Core.DTO.LoginDTO -> Template.Core.Entity.ApplicationUser (Destination member list)

Unmapped properties:
CreatedBy
CreatedOn
LastModifiedBy
LastModifiedOn
IsDeleted
UserType
FirstName
LastName
DateOfBirth
IsActive
Id
NormalizedUserName
Email
NormalizedEmail
EmailConfirmed
PasswordHash
SecurityStamp
ConcurrencyStamp
PhoneNumber
PhoneNumberConfirmed
TwoFactorEnabled
LockoutEnd
LockoutEnabled
AccessFailedCount
:  Controller: Auth  Action: Post ---> AutoMapper.AutoMapperConfigurationException: 
Unmapped members were found. Review the types and members below.
Add a custom mapping expression, ignore, add a custom resolver, or modify the source/destination type
For no matching constructor, add a no-arg ctor, add optional arguments, or map all of the constructor parameters
===================================================================
AutoMapper created this type map for you, but your types cannot be mapped using the current configuration.
LoginDTO -> ApplicationUser (Destination member list)
Template.Core.DTO.LoginDTO -> Template.Core.Entity.ApplicationUser (Destination member list)

Unmapped properties:
CreatedBy
CreatedOn
LastModifiedBy
LastModifiedOn
IsDeleted
UserType
FirstName
LastName
DateOfBirth
IsActive
Id
NormalizedUserName
Email
NormalizedEmail
EmailConfirmed
PasswordHash
SecurityStamp
ConcurrencyStamp
PhoneNumber
PhoneNumberConfirmed
TwoFactorEnabled
LockoutEnd
LockoutEnabled
AccessFailedCount

   at AutoMapper.ConfigurationValidator.AssertConfigurationIsValid(IEnumerable`1 typeMaps) in C:\projects\automapper\src\AutoMapper\ConfigurationValidator.cs:line 48
   at lambda_method(Closure , LoginDTO , ApplicationUser , ResolutionContext )
   at lambda_method(Closure , Object , Object , ResolutionContext )
   at AutoMapper.Mapper.AutoMapper.IMapper.Map[TDestination](Object source) in C:\projects\automapper\src\AutoMapper\Mapper.cs:line 207
   at Template.Service.AuthService.Login(LoginDTO credentials) in D:\Projects\NetCoreTemplate\Template\Template.Service\AuthService.cs:line 72
   at Template.Controllers.AuthController.Post(LoginDTO credentials) in D:\Projects\NetCoreTemplate\Template\Template\Controllers\AuthController.cs:line 34
   at Microsoft.AspNetCore.Mvc.Internal.ActionMethodExecutor.TaskOfIActionResultExecutor.Execute(IActionResultTypeMapper mapper, ObjectMethodExecutor executor, Object controller, Object[] arguments)
   at System.Threading.Tasks.ValueTask`1.get_Result()
   at Microsoft.AspNetCore.Mvc.Internal.ControllerActionInvoker.InvokeActionMethodAsync()
   at Microsoft.AspNetCore.Mvc.Internal.ControllerActionInvoker.InvokeNextActionFilterAsync()
   at Microsoft.AspNetCore.Mvc.Internal.ControllerActionInvoker.Rethrow(ActionExecutedContext context)
   at Microsoft.AspNetCore.Mvc.Internal.ControllerActionInvoker.Next(State& next, Scope& scope, Object& state, Boolean& isCompleted)
   at Microsoft.AspNetCore.Mvc.Internal.ControllerActionInvoker.InvokeInnerFilterAsync()
   at Microsoft.AspNetCore.Mvc.Internal.ResourceInvoker.InvokeNextExceptionFilterAsync()
   --- End of inner exception stack trace ---|url: https://localhost/api/Auth/login|action: Post
